<?xml version="1.0" ?>
<robot name="mcfoamy" xmlns:xacro="http://www.ros.org/wiki/xacro">
  
  

  
    <gazebo>
      <plugin filename="/home/eitan/mcfoamy_gazebo/devel/lib/libgazebo_plane.so" name="gazebo_plane">
     </plugin>
    </gazebo>
    <link name="world"/>   

    <joint name="fixed" type="floating">
      <parent link="world"/>
      <child link="airframe"/>
    </joint>

    <link name="airframe">
      <inertial>
        <mass value=".6"/>
        <origin xyz="0 0 0"/>
        <inertia ixx="0.005" ixy="0.0" ixz="0.0" iyy="0.021" iyz="0.0" izz="0.023"/>
      </inertial>
      <visual>
        <origin rpy="0 0 0" xyz="0 0 0"/>
        <geometry>
          <mesh filename="package://gazebo_example/meshes/mcfoamy_mod.STL"/>
        </geometry>
      </visual>
      <collision>
        <origin rpy="0 0 0" xyz="0 0 0"/>
        <geometry>
          <box size="0.2 1.0 0.2"/>
        </geometry>
      </collision>
    </link>


  <joint name="camera_joint" type="fixed">
    <axis xyz="1 0 0" />
    <origin xyz="0 0 .15" rpy="0 0 0"/>
    <parent link="airframe"/>
    <child link="kinect"/>
  </joint>

  <!-- Camera -->
  <link name="kinect">
    <collision>
      <origin xyz="0 0 0" rpy="0 0 0"/>
      <geometry>
    <box size="0.073000 0.276000 0.072000"/>
      </geometry>
    </collision>

    <visual>
      <origin xyz="0 0 0" rpy="0 0 0"/>
      <geometry>
    <box size="0.073000 0.276000 0.072000"/>
      </geometry>
      <material name="red"/>
    </visual>

    <inertial>
      <mass value="1e-19" />
      <origin xyz="0 0 0" rpy="0 0 0"/>
      <inertia ixx="1e-19" ixy="0" ixz="0" iyy="1e-19" iyz="0" izz="1e-19" />
    </inertial>
  </link>

    <gazebo reference="kinect">
    <sensor type="depth" name="camera">
      <update_rate>30.0</update_rate>
      <camera>
        <horizontal_fov>1.50098</horizontal_fov>
        <image>
          <width>640</width>
          <height>480</height>
          <format>R8G8B8</format>
        </image>
        <clip>
          <near>0.2</near>
          <far>25</far>
        </clip>
      </camera>
        <plugin name="camera_plugin" filename="libgazebo_ros_openni_kinect.so">
          <baseline>0.2</baseline>
          <alwaysOn>true</alwaysOn>
          <updateRate>0.0</updateRate>
          <cameraName>camera_ir</cameraName>
          <imageTopicName>/camera/depth/image_raw</imageTopicName>
          <cameraInfoTopicName>/camera/depth/camera_info</cameraInfoTopicName>
          <depthImageTopicName>/camera/depth/image_raw</depthImageTopicName>
          <depthImageInfoTopicName>/camera/depth/camera_info</depthImageInfoTopicName>
          <pointCloudTopicName>/camera/depth/points</pointCloudTopicName>
          <frameName>kinect_camera_frame</frameName>
          <pointCloudCutoff>0.2</pointCloudCutoff>
          <pointCloudCutoffMax>25.0</pointCloudCutoffMax>
          <distortionK1>0</distortionK1>
          <distortionK2>0</distortionK2>
          <distortionK3>0</distortionK3>
          <distortionT1>0</distortionT1>
          <distortionT2>0</distortionT2>
          <CxPrime>0</CxPrime>
          <Cx>0</Cx>
          <Cy>0</Cy>
          <focalLength>0</focalLength>
          <hackBaseline>0</hackBaseline>
        </plugin>
    </sensor>
  </gazebo>




</robot>
